Workbook

Sheet KAYIT
B1: Firma ünvanı
B2: Adres
B3: SGK SİCİL | D3: İŞKOLU
B4: Ay
B5: Yıl | D5: Tehlike Sınıfı:
B6: Tarih | D6: Geçerlilik Tarih:
B7: İşveren /İ. Vekili | D7: Telefon: | F7: TC :
B8: İş Güvenliği Uzmanı | D8: Sertifika No: | F8: TC : | J8: Tel:
B9: İşyeri Hekimi | D9: Sertifika No: | F9: TC : | J9: Tel:
B10: Çalışan Temsilcisi | D10: Eğitim Tarihi: | F10: TC : | J10: Tel:
B11: Çalışan Temsilcisi | D11: Eğitim Tarihi: | F11: TC : | J11: Tel:
B12: Destek Elemanı/ Koordinatör | D12: Telefon: | F12: TC :
B13: Tüm Br. Bilgi Sahibi Kişi | D13: Telefon: | F13: TC :
B14: Adep Ekip Yenileme Tarihi
B15: Adep Ekip Yenileme No
B18: TC | C18: SÖNDÜRME EKİBİ | D18: ADI SOYADI | E18: TELEFON
A19: 1 | C19: Ekip Başkanı
A20: 2 | C20: Ekip Başkan Yardımcısı
A21: 3 | C21: Üye
A22: 4 | C22: Üye
B24: TC | C24: KURTARMA EKİBİ | D24: ADI SOYADI | E24: TELEFON
A25: 1 | C25: Ekip Başkanı
A26: 2 | C26: Ekip Başkan Yardımcısı
A27: 3 | C27: Üye
A28: 4 | C28: Üye
B30: TC | C30: KORUMA EKİBİ | D30: ADI SOYADI | E30: TELEFON
A31: 1 | C31: Ekip Başkanı
A32: 2 | C32: Ekip Başkan Yardımcısı
A33: 3 | C33: Üye
A34: 4 | C34: Üye
B36: TC | C36: İLKYARDIM EKİBİ | D36: ADI SOYADI | E36: TELEFON
A37: 1 | C37: Ekip Başkanı
A38: 2 | C38: Ekip Başkan Yardımcısı
A39: 3 | C39: Üye
A40: 4 | C40: Üye
A41: 5 | C41: Üye
A42: 6 | C42: Üye
A43: 7 | C43: Üye
A44: 8 | C44: Üye
A45: 9 | C45: Üye
...

Sheet İNDEKS-1
C7: =KAYIT!C1 -> 0
B18: =KAYIT!C2 -> 0
B20: =KAYIT!C3 -> 0
C34: İŞ SAĞLIĞI VE
C39: GÜVENLİĞİ DOSYASI
E53: =KAYIT!C4 -> 0
E54: =KAYIT!C5 -> 0
C67: OSGB DÖKÜMANLARI İNDEKS
C69: 1. ÖN DENETİM/UYGUNSUZLUK RAPORLARI
C70: 2. SÖZLEŞME-BAKANLIK SÖZLEŞMELER
C71: 3. İŞLETME BELGELERİ NUMUNELERİ
C72: a. RUHSAT
C73: b. FAALİYET İZİN BELGESİ
C74: c. EKİPMAN LİSTESİ
C75: d. PERSONEL LİSTESİ
C76: 4. YILLIK ÇALIŞMA PLANI-YILLIK EĞİTİM PLANI
C77: 5. İÇ EMNİYET YÖNETMELİĞİ VE DİSİPLİN YÖNETMELİĞİ PROSEDÜRÜ
C78: 6. ATAMA YAZILARI
C79: 7. PERSONEL EĞİTİM İMZA FÖYLERİ
... C92: 20. ARŞİV
C105: =C7 -> 0
E128: 1
C147: - ÖN DENETİM RAPORLARI
C148: - UYGUNSUZLUK RAPORLARI
C158: =C105 -> 0
E181: =E128+1 -> 2
C200: - SÖZLEŞME
C201: - BAKANLIK SÖZLEŞMELERİ
C211: =C158 -> 0
E234: =E181+1 -> 3
C253: - İŞLETME BELGELERİ
C254: (RUHSAT/EKİPMAN LİSTESİ/PERSONEL LİSTESİ)
C264: =C211 -> 0
E287: =E234+1 -> 4
C306: - YILLIK ÇALIŞMA PLANI
C307: - YILLIK EĞİTİM PLANI
C317: =C264 -> 0
E340: =E287+1 -> 5
C359: - İÇ EMNİYET YÖNETMELİĞİ
C360: - DİSİPLİN YÖNETMELİĞİ PROSEDÜRÜ
...

Sheet YILLIK ÇALIŞMA
B1: İŞ SAĞLIĞI ve GÜVENLİĞİ YILLIK ÇALIŞMA PLANI
B2: 2024 YILI ÇALIŞMA PLANI
B3: İş Yeri Unvanı: | C3: =KAYIT!C1 -> 0 | G3: İş Yeri Adresi: | I3: =KAYIT!C2 -> 0
B4: İş Yeri Sicil No: | C4: =KAYIT!C3 -> 0
B5: PERİYODİK FAALİYETLER | C5: PERİYOT | D5: SORUMLU | E5: İLGİLİ MEVZUAT | F5: MEVCUT DURUM | G5: A Y L A R
G6: OCAK | H6: ŞUBAT | I6: MART | J6: NİSAN | K6: MAYIS | L6: HAZİRAN | M6: TEMMUZ | N6: AĞUSTOS | O6: EYLÜL | P6: EKİM | Q6: KASIM | R6: ARALIK
B7: Yıllık Çalışma Planının Hazırlanması | C7: 1 Kez / Yıl | D7: İşveren İş Güv Uzmanı İşyeri Hekimi | E7: 29.12.2012/28512 / Değişiklik 18.12.2014/29209 / İş Sağlığı Ve Güvenliği Hizmetleri Yönetmeliği
B8: Yıllık Eğitim Planın Yapılması | C8: 1 Kez / Yıl | D8: İşveren İş Güv Uzmanı İşyeri Hekimi | E8: 15.05.2013-28648 / Çalışanların İş Sağlığı ve Güvenliği Eğitimlerinin Usul ve Esasları Hakkında Yönetmelik
B9: İSG Kurul Toplantısı | C9: 1 Kez / 1 Ay 1 Kez / 2 Ay 1 Kez / 3 Ay | D9: İSG Kurulu | E9: 18.01.2013-28532 / İş Sağlığı Ve Güvenliği Kurulları Hakkında Yönetmelik / Madde 9 (1)-a | F9: MUAF
B10: Risk Değerlendirme Ekibinin Eğitilmesi | C10: 1 Kez | D10: İş Güv Uzmanı İş Yeri Hekimi | E10: 15.05.2013-28648 / Çalışanların İş Sağlığı ve Güvenliği Eğitimlerinin Usul ve Esasları Hakkında Yönetmelik 29.12.2012/28512 / İş Sağlığı Ve Güvenliği Risk Değerlendirmesi Yönetmeliği
B11: Risk Değerlendirmesi Kontrolü / Yapılması | C11: 1 Kez / 2 Yıl 1 Kez / 4 Yıl 1 Kez / 6 Yıl | D11: Risk Değerlendirme Ekibi | E11: 29.12.2012/28512 / Değişiklik 18.12.2014/29209 / İş Sağlığı Ve Güvenliği Hizmetleri Yönetmeliği 29.12.2012/28512 / İş Sağlığı Ve Güvenliği Risk Değerlendirmesi Yönetmeliği
B12: İşyeri Ortam Ölçümlerinin Kontrolü / Yapılması *Kimyasal Etkenler Ölçümü *Fiziksel Etkenler Ölçümü *Biyolojik Etkenler Ölçümü | C12: 1 Kez | D12: İşveren İş Güv Uzmanı İş Yeri Hekimi | E12: 29.12.2012/28512 / Değişiklik 18.12.2014/29209 / İş Sağlığı Ve Güvenliği Hizmetleri Yönetmeliği 20.08.2013/28741 / İş Hijyeni Ölçüm, Test Ve Analizi Yapan Lab. Hak. Yön.
B13: Çalışanların Kişisel Maruziyet Ölçümleri Kontrolü / Sağlanması | C13: Belirli Periyot | D13: İşveren İş Güv Uzmanı İşyeri Hekimi | E13: 29.12.2012/28512 / Değişiklik 18.12.2014/29209 / İş Sağlığı Ve Güvenliği Hizmetleri Yönetmeliği 20.08.2013/28741 / İş Hijyeni Ölçüm, Test Ve Analizi Yapan Lab. Hak. Yön.
B14: Kaldırma İletme araçlarının periyodik kontrollerinin ve testlerinin yaptırılması | C14: 1 / 12 Ay | D14: İşveren | E14: 25.04.2013 -28628 / İş Ekipmanlarının Kullanımında Sağlık Ve Güvenlik Şartları Yönetmeliği / Ek III-Tablo.2
B15: Basınçlı Kapların periyodik kontrollerinin ve testlerinin yaptırılması | C15: 1 / 12 Ay | D15: İşveren | E15: 25.04.2013 -28628 / İş Ekipmanlarının Kullanımında Sağlık Ve Güvenlik Şartları Yönetmeliği / Ek III-Tablo.1
B16: Elektrik Tesisatların Periyodik İç tesisat ve Topraklama Kontrollerinin ve testlerinin yaptırılması | C16: 1 / 12 Ay | D16: İşveren | E16: 25.04.2013 -28628 / İş Ekipmanlarının Kullanımında Sağlık Ve Güvenlik Şartları Yönetmeliği / Ek III-Tablo.3
B17: Acil Durum Planının Kontrolü / Güncellenmesi | C17: 1 Kez / 2 Yıl 1 Kez / 4 Yıl 1 Kez / 6 Yıl | D17: İşveren İş Güv. Uzm. İş Yeri Hekimi | E17: 18.06.2013-28681 / İşyerlerinde Acil Durumlar Hakkında Yönetmelik Madde 14
B18: Acil Durum Ekiplerinin Güncellenmesi | C18: 2 Kez / 1 Yıl | D18: İşveren İş Güv. Uzm. İş Yeri Hekimi | E18: 18.06.2013-28681 / İşyerlerinde Acil Durumlar Hakkında Yönetmelik Madde 14
B19: İş sağlığı ve Güvenliği Uyarı ikaz İşaret Levhalarının Kontrolü / Tespiti ve Asılması | C19: 1 Kez | D19: İşveren İş Güv. Uzm. | E19: 11.09.2013 - 28672 sayılı Sağlık ve Güvenlik İşaretleri Yönetmeliği Madde:5/1
B20: Firma Acil Durum Tahliye Projesi Kontrolü / Oluşturulması (Kaçış yollarının, yangın merdivenlerinin, acil durum asansörlerinin, yangın dolaplarının, itfaiye su verme ve alma ağızlarının, toplanma alanın ve yangın pompalarının yerlerinin renkli olarak işaretlendiği proje) | C20: 1 Kez / 2 Yıl 1 Kez / 4 Yıl 1 Kez / 6 Yıl | D20: İşveren İş Güv. Uzm. İş Yeri Hekimi | E20: 18.06.2013-28681 / İşyerlerinde Acil Durumlar Hakkında Yönetmelik Madde 15 19/12/2007-26735 / Binaların Yangından Korunması HakkındaYönetmelik
B21: Çalışanların İSG Eğitimleri (Genel-Sağlık-Teknik Konular) | C21: 8 Saat / 12 Ay 12 Saat / 24 Ay 16 Saat / 36 Ay | D21: İş Güv Uzmanı İş Yeri Hekimi | E21: 15.05.2013-28648 / Çalışanların İş Sağlığı ve Güvenliği Eğitimlerinin Usul ve Esasları Hakkında Yönetmelik / Madde 6 (4)-b / Madde 15 | F21: Çalışanların eğitimi işyerinin değişken yapısı ve personel sirkülasyonunun yoğunluğu nedeniyle işyerinde çalışmaya başlayan her çalışana bireysel veya toplu olarak verilmekte ve belgelenmektedir
B22: İş Sağlığı ve Güvenliği Kurulu Eğitimi | C22: 1 Kez / 2 Yıl 1 Kez / 4 Yıl 1 Kez / 6 Yıl | D22: İş Güv Uzmanı İş Yeri Hekimi | E22: R.G. 18 Ocak 2013/28532 / İş Sağlığı ve Güvenliği Kurulları Hakkında Yönetmelik / Madde 7 | F22: MUAF
B23: Yangın Ekipleri Eğitimi ve Yangın söndürme cihazların kontrolü | C23: 2 Kez / Yıl | D23: İş Güv Uzmanı İş Yeri Hekimi | E23: R.G. 19 Aralık 2007/26735 / Binaların Yangından Korunması Hakkındaki Yönetmelik / Madde 129
B24: Tüm Çalışanların Acil Durum Planı Bilgilendirilmesi / Eğitimi | C24: 1 Kez / 2 Yıl 1 Kez / 4 Yıl 1 Kez / 6 Yıl | D24: İşveren İş Güv. Uzm. İş Yeri Hekimi | E24: 18.06.2013-28681 / İşyerlerinde Acil Durumlar Hakkında Yönetmelik Madde 15
B25: İşe Giriş ve Yıllık Periyodik Muayenelerin Kontrolü / Yapılması | C25: 1 kez/1 Yıl 1 kez/3 Yıl 1 kez/5 Yıl | D25: İşveren İşyeri Hekimi Diğ. Sağlık Personeli | E25: 20.07.2013-28713 Deşiklik 18.12.2014/29209 / İşyeri Hekimi ve Diğer Sağlık Personelinin Görev, Yetki, Sorumluluk ve Eğitimleri Hakkında Yönetmelik / Madde 9.c.3 | F25: Çalışanların sağlık kontrolleri işyeri hekiminin belirlediği periyotlarda ve işe başlayan her personeli kapsayacak şekilde yapılmaktadır
B26: Acil durum Tahliye Tatbikatının Yapılması ve Tatbikat Raporunun Tutulması | C26: 1 Kez / Yıl | D26: İş Güv. Uzm. İş Yeri Hekimi | E26: 18.06.2013-28681 / İşyerlerinde Acil Durumlar Hakkında Yönetmelik Madde 13
B27: İçme Suyu Temininin Kontrolü / Sağlanması ve Uygunluğunun Analizi | C27: Belirli Periyot | D27: İşyeri Hekimi DSP | E27: 20.07.2013-28713 Deşiklik 18.12.2014/29209 / İşyeri Hekimi ve Diğer Sağlık Personelinin Görev, Yetki, Sorumluluk ve Eğitimleri Hakkında Yönetmelik / Madde 2.a.5
B28: Çalışanların Sosyal Alanlarının Fiziksel Uygunluğunun ve Hijyen Şartlarının Sağlanması / Takibi | C28: Belirli Periyot | D28: İşveren İş Güv Uzmanı | E28: 17.07.2013/28710 - İşyeri Bina Ve Eklentilerinde Alınacak Sağlık Ve Güvenlik Önlemlerine İlişkin Yönetmelik
B29: İşyerinde İSG gözetimlerininin / denetimlerinin yapılması | C29: Sürekli | D29: İşveren İş Güv Uzmanı İşyeri Hekimi Çal. Temsilcisi | E29: 29.12.2012-28512 / İş Güvenliği Uzmanlarının Görev, Yetki, Sorumluluk ve Eğitimleri Hakkında Yönetmelik Madde 9 20.07.2013-28713 Deşiklik 18.12.2014/29209 / İşyeri Hekimi ve Diğer Sağlık Personelinin Görev, Yetki, Sorumluluk ve Eğitimleri Hakkında Yönetmelik
B30: İş Kazası ve Meslek Hastalıkları Kaydı (Ramak kala olay, İlkyardım uygulanan kaza, İş günü kayıplı kaza, İş kazası) | C30: Sürekli | D30: İşveren İş Güv Uzmanı İşyeri Hekimi Çal. Temsilcisi | E30: 29.12.2012-28512 / İş Güvenliği Uzmanlarının Görev, Yetki, Sorumluluk ve Eğitimleri Hakkında Yönetmelik Madde 9 20.07.2013-28713 Deşiklik 18.12.2014/29209 / İşyeri Hekimi ve Diğer Sağlık Personelinin Görev, Yetki, Sorumluluk ve Eğitimleri Hakkında Yönetmelik
B31: Ek -2 Yıllık Değerlendirme Raporunun Tutulması | C31: 1 Kez / Yıl | D31: İşveren İş Güv Uzmanı İşyeri Hekimi | E31: 29.12.2012-28512 / İş Güvenliği Uzmanlarının Görev, Yetki, Sorumluluk ve Eğitimleri Hakkında Yönetmelik Madde 9 20.07.2013-28713 Deşiklik 18.12.2014/29209 / İşyeri Hekimi ve Diğer Sağlık Personelinin Görev, Yetki, Sorumluluk ve Eğitimleri Hakkında Yönetmelik
B33: İş Güvenliği Uzmanı | E33: İşyeri Hekimi | H33: İşveren / İ.Vekili
B34: =KAYIT!C8 -> 0 | E34: =KAYIT!C9 -> 0 | H34: =KAYIT!C7 -> 0

Sheet YILLIK EĞİTİM 
B1: İŞ SAĞLIĞI ve GÜVENLİĞİ YILLIK EĞİTİM PLANI
B2: 2024 YILI EĞİTİM PLANI
B3: İş Yeri Unvanı: | D3: =KAYIT!C1 -> 0 | F3: İş Yeri Adresi: | G3: =KAYIT!C2 -> 0
B4: İş Yeri Sicil No: | D4: =KAYIT!C3 -> 0
B5: Sıra No | C5: EĞİTİM KONUSU | D5: Eğitimi Verecek Kişi/Kuruluş | E5: Planlanan Tarih | F5: Gerçekleşen Tarih | G5: AÇIKLAMALAR
B6: 1 | C6: Genel Konular a) Çalışma mevzuatı ile ilgili bilgiler b) Çalışanların yasal hak ve sorumlulukları c) İşyeri temizliği ve düzeni d) İş kazası ve meslek hastalığından doğan hukuki sonuçlar | D6: İş Güvenliği Uzmanı | E6: SÜREKLİ
B7: 2 | C7: Sağlık Konuları a) Meslek hastalıklarının sebepleri b) Hastalıktan korunma prensipleri ve korunma tekniklerinin uygulaması c) Biyolojik ve psikososyal risk etmenleri d) İlkyardım | D7: İşyeri Hekimi | E7: SÜREKLİ
B8: 3 | C8: Teknik Konular a) Kimyasal, fiziksel ve ergonomik risk etmenleri b) Elle kaldırma ve taşıma c) Parlama patlama, yangın ve yangından korunma d) İş ekipmanlarının güvenli kullanımı e) Ekranlı araçlarla çalışma f) Elektrik tehlikeleri, riskleri ve önlemleri g) İş kazalarının sebepleri ve korunma prensipleri ile tekniklerin uygulanması h) Güvenlik ve sağlık işaretleri i) Kişisel koruyucu donanım kullanımı j) İş sağlığı ve güvenliği genel kuralları ve güvenlik kültürü k) Tahliye ve kurtarma | D8: İş Güvenliği Uzmanı | E8: SÜREKLİ
B9: 4 | C9: Risk Değerlendirme Ekibi Eğitimi | D9: İş Güvenliği Uzmanı | E9: OCAK
B10: 5 | C10: İş Sağlığı ve Güvenliği Kurulu Eğitimi | D10: İş Güvenliği Uzmanı | E10: MUAF
B11: 6 | C11: Çalışan Temsilcisi Eğitimi | D11: İş Güvenliği Uzmanı | E11: OCAK
B12: 7 | C12: Acil Durum Planı Pers. Bilgilendirme Eğitimi | D12: İş Güvenliği Uzmanı/ İş Yeri Hekimi | E12: OCAK
B13: 8 | C13: İlk Yardımcı Eğitimi | D13: Yetkili Eğitim Kuruluşu | E13: 3 YIL
B14: 9 | C14: Hijyen Eğitimi | D14: Yetkili Kuruluş | E14: ŞUBAT
B15: 10 | C15: Destek Elemanı ve Ekipler Eğitimi | D15: İş Güvenliği Uzmanı | E15: OCAK
B16: 11 | C16: Mesleki Eğitimler /Mesleki Yeterlilik | D16: Yetkili Eğitim Kuruluşu | E16: SÜREKLİ
B17: 12 | C17: İşbaşı İsg Eğitimleri | D17: İş Güvenliği Uzmanı | E17: SÜREKLİ
B18: *EĞİTİMLERİN SÜRESİ : Az tehlikeli işyerleri için en az 8 saat, Tehlikeli işyerleri için en az 12 saat, Çok tehlikeli işyerleri için en az 16 saat olarak her çalışan için düzenlenecektir. *EĞİTİMLERİN TEKRARI : Çok tehlikeli sınıfta yer alan işyerlerinde yılda en az 1 defa, Tehlikeli sınıfta yer alan işyerlerinde 2 yılda en az 1 defa, Az tehlikeli sınıfta yer alan işyerlerinde 3 yılda en az 1 defa. İş kazası geçiren veya meslek hastalığına yakalanan çalışana işe dönüşünde çalışmaya başlamadan önce, kazanın veya meslek hastalığının sebepleri, korunma yolları ve güvenli çalışma yöntemleri ile ilgili ilave eğitim verilir. Herhangi bir sebeple altı aydan fazla süreyle işten uzak kalanlara, tekrar işe başlatılmadan önce bilgi yenileme eğitimi verilir. *HİJYEN EĞİTİMİ ALINACAK İŞYERLERİ : Gıda üretim ve perakende iş yerleri. İnsani tüketim amaçlı sular ile doğal mineralli suların üretimini yapan iş yerleri. Kaplıca, hamam, sauna, berber, kuaför, dövme ve pirsing yapılan yerler, masaj ve güzellik salonları ve benzeri yerler. Otel, motel, pansiyon ve misafirhane gibi yerler. Komisyon tarafından hijyen eğitimi verilmesi uygun görülen diğer iş kolları. *EĞİTİMLERİN AMACI : Çalışanlarda iş sağlığı ve güvenliğine yönelik davranış değişikliği sağlamayı ve eğitimlerde aktarılan bilgilerin öneminin çalışanlarca kavranmasını sağlamaktır. *İlk Yardım Eğitimi Alması Gereken Personel Sayısı: İlk Yardım Yönetmeliği'ne göre Çok Tehlikeli sınıfta yer alan işyerlerinde her 10 kişiden bir kişi, Tehlikeli sınıfta yer alan işyerlerinde 15 kişiden bir kişi, Az Tehlikeli Sınıfta yer alan işyerlerinde her 20 kişiden bir kişi ilkyardım eğitimi almış olmalıdır.
B20: İş Güvenliği Uzmanı | D20: İşyeri Hekimi | G20: İşveren / İ.Vekili
B21: =KAYIT!C8 -> 0 | D21: =KAYIT!C9 -> 0 | G21: =KAYIT!C7 -> 0

Sheet YILLIK DEĞERLENDİRME
A1: EK-2
A2: YILLIK DEĞERLENDİRME RAPORU (2023)
A3: İş Yerinin:
A4: Unvanı : | C4: =KAYIT!C1 -> 0
A5: SGK/Bölge Müdürlüğü Sicil No: | C5: =KAYIT!C3 -> 0
A6: Adres : | C6: =KAYIT!C2 -> 0
A7: Tel ve Fax : | D7: E-posta:
A8: İşkolu : | C8: =KAYIT!E3
A9: Çalışan Sayısı: | C9: Erkek : 4 | D9: Kadın: | E9: Genç: | F9: Çocuk: | G9: Toplam:
A11: Sıra No. | B11: Yapılan çalışmalar | C11: Tarih | D11: Yapan Kişi ve Unvanı | E11: Tekrar Sayısı | F11: Kullanılan Yöntem | G11: Sonuç ve Yorum
A12: 1 | B12: Risk değerlendirmesi | C12: =KAYIT!C6 -> 0 | D12: =KAYIT!C8 -> 0 | E12: 4 yılda 1 | F12: FINE KINNEY | G12: Yapılan risk analizinde belirtilen hususlar ve düzeltici önleyici tedbirlerin alınmasına devam edilmektedir. Sahada belirli periyotlarda kontrol yapılarak tespit öneri defterine önerilerde bulunulmuştur.
D13: İş Güvenliği Uzmanı
D14: =KAYIT!C9 -> 0
B15: Risk değerlendirmesi | C15: 42793 | D15: İşyeri Hekimi | E15: İşveren İş Güv Uzmanı İşyeri Hekimi | F15: İşveren İş Güv Uzmanı İşyeri Hekimi | G15: İşveren İş Güv Uzmanı İşyeri Hekimi
A16: 2 | B16: Ortam ölçümleri | C16: - | D16: Onaylanmış kuruluş | E16: Gerekli Görülen durumlarda | F16: İş Hij. Ölçüm, Test Ve Analiz Lab. Hk. Yön. Göre yapılan ölçümler | G16: Firmada yapılan iş ve işlemler göz önünde bulundurulduğunda, risk değerlendirme ekibinin de tavsiyesiyle ortam ölçümlerine gerek görülmemiştir.
A17: 3 | B17: İşe giriş muayeneleri | C17: Her işe girişte ve Tüm personele | D17: =D14 -> 0 | E17: İşe yeni girişlerde ve 3 yılda 1 | F17: Fiziki Muayene | G17: Firmada işe başlayacak personelin görevlendirileceği bölüm ve yapacağı iş ve işlemlerde mevcut sağlık durumunu etkileyebilecek faktörlere istinaden işyeri hekimince belirlenen tetkikler yaptırılmaktadır.
B18: Risk değerlendirmesi | C18: 42793 | D18: İşyeri Hekimi | E18: İşveren İş Güv Uzmanı İşyeri Hekimi | F18: İşveren İş Güv Uzmanı İşyeri Hekimi | G18: İşveren İş Güv Uzmanı İşyeri Hekimi
A19: 4 | B19: Periyodik muayeneler | C19: - | D19: - | E19: Yılda 1 | F19: Volt Amper Metrik (Üç uçlu Karşılaştırmalı ) Yöntem | G19: Yapılan testler sonucunda topraklama ölçümleri sınır değerlerin altında bulunmaktadır.
D20: Elektrik Mühendisi
C21: - | D21: - | E21: Yılda 1 | F21: Hidrostatik deney, Emniyet ventilli deney, kaldırma testi, mekanik dayanıklılık testi | G21: Kaldırma araçları ve basınçlı kapların yapılan testlerinde makine ve aletlerin çalışmasında sakınca bulunmamıştır.
B22: Risk değerlendirmesi | D22: Makine Mühendisi | F22: İşveren İş Güv Uzmanı İşyeri Hekimi | G22: İşveren İş Güv Uzmanı İşyeri Hekimi
A23: 5 | B23: Radyolojik analizler | C23: 2025 | D23: =D14 -> 0 | E23: İşe yeni girişlerde ve yılda 1 | F23: PA AC Grafisi | G23: 2022 yılında, İşe girişlerde ve periyodik muayenelerde personelin PA AC grafisi çekilerek akciğerde aktif lezyon olup olmadığı değerlendirildi. Herhangi bir olumsuz sonuca rastlanmamıştır.
B24: Risk değerlendirmesi | C24: 42793 | D24: İşyeri Hekimi | E24: İşveren İş Güv Uzmanı İşyeri Hekimi | F24: İşveren İş Güv Uzmanı İşyeri Hekimi | G24: İşveren İş Güv Uzmanı İşyeri Hekimi
A25: 6 | B25: Biyolojik analizler | C25: - | D25: Onaylanmış kuruluş | E25: Gerekli Görülen durumlarda | F25: - | G25: Kuyu suyuna ait bakteriyolojik testler Halk sağlığı laboratuvarına belirli periyorlarda yaptırılmaktadır. Değerlendirme sonuçlarında uygunsuz bir sonuç bulunmamıştır.
G26: Sayfa1/2
A27: 7 | B27: Toksikolojik analizler | C27: - | D27: Onaylanmış kuruluş | E27: Gerekli Görülen durumlarda | F27: İş Hijyeni Ölçüm, Test Ve Analiz Lab. Hk. Yön. Göre yapılan ölçümler | G27: Kuyu suyuna ait kimyasal testler Halk sağlığı laboratuvarına belirli periyorlarda yaptırılmaktadır. Değerlendirme sonuçlarında uygunsuz bir sonuç bulunmamıştır.
A28: 8 | B28: Fizyolojik testler | C28: - | D28: - | E28: - | F28: - | G28: -
A29: 9 | B29: Psikolojik testler | C29: - | D29: - | E29: - | F29: - | G29: -
A30: 10 | B30: Eğitim çalışmaları | C30: 2022 yılı içerisinde | D30: =D12 -> 0 | E30: Tüm personele toplam 12 Saat/Yıllık | F30: Slayt | G30: 2022 yılında tüm personel iş güvenliği uzmanı ve işyeri hekimi tarafından mevzuatta belirtilen süreler kadar İSG Eğitimi verilmiştir.
D31: İş Güvenliği Uzmanı
D32: =D14 -> 0
B33: Risk değerlendirmesi | C33: 42793 | D33: İşyeri Hekimi | E33: İşveren İş Güv Uzmanı İşyeri Hekimi | F33: İşveren İş Güv Uzmanı İşyeri Hekimi | G33: İşveren İş Güv Uzmanı İşyeri Hekimi
A34: 11 | B34: Diğer çalışmalar | C34: - | D34: Yangın tatbikatı ….................. Yangın firması | E34: Yıllık | F34: - | G34: Firmanın faaliyet alanında olası acil durumlarda yapılacaklar bir eylem planı çerçevesinde hazırlanmış ve bilgilendirmesi çalışanlara aktarılmıştır.
D41: Tarih: 22/09/2025
B43: İş Güvenliği Uzmanı | D43: İşveren / İ.Vekili | F43: İşyeri Hekimi
B44: =D12 -> 0 | D44: =KAYIT!C7 -> 0 | F44: =D14 -> 0
G69: Sayfa2/2

Sheet DİSİPLİN YÖNETMENLİĞİ
C10: DİSİPLİN YÖNETMELİĞİ PROSEDÜRÜ
F47: =KAYIT!C6 -> 0
C50: =KAYIT!C1 -> 0
D61: DİSİPLİN YÖNETMELİĞİ PROSEDÜRÜ
D63: =KAYIT!C1 -> 0
C68: İşyeri Unvanı | E68: =KAYIT!C1 -> 0 | H68: Hazırlama/ Güncelleme Tarihi | I68: =KAYIT!C6 -> 0
C71: İşyeri Adresi | E71: =KAYIT!C2 -> 0
C74: İşyeri Sicil No | E74: =KAYIT!C3 -> 0
F79: DİSİPLİN YÖNETMELİĞİ
C81: 1. AMAÇ
C82: =KAYIT!C1 -> 0
C83: bünyesi içerisinde uyumlu ve verimli bir çalışma ortamı yaratabilmek, çalışanların uymaları gereken kuralları, yükümlülükleri ortaya koymak, yönetmelik kapsamında yer alan kurallara aykırı düşen veya bu kuralları ihlal eden tutum, davranış ve olayların ortaya çıkması durumunda izlenecek süreçleri tanımlamak.
C89: 2. KAPSAM
C90: Tüm çalışanlar bu prosedür kapsamındadır. Prosedürün uygulanması ile ilgili sorumluluklar aşağıdaki şekildedir: İnsan Kaynakları, prosedürün uygulama, takip ve yetki kullanımından; Birimlerini temsil eden üst düzey yöneticiler, ekiplerinde çalışan kişilere bu yönetmelik kapsamındaki kuralların aktarılmasından, uygulamayı izleyerek gerekli durumlarda uyarılarda bulunulmasından ve prosedürün güncellenmesi ihtiyacını fark etmeleri durumunda İnsan Kaynakları Bölümü’nü bilgilendirmekten; Disiplin Kurulu, kararlarının alınması aşamasında yönetmelik kurallarına uygun hareket edilmesinden ve kurula gelen dosyaların gizliliğinden, sorumludur.
C101: 3. UYGULAMA
C102: 3.1. Çalışan, iş görme borcunu 4857 sayılı İş Kanunu’nda hüküm altına alınan işçinin işi kendisinin yapması, işin özenle yapılması, itaat borcu, özel haller, kuruma sadakat borcu ve rekabet etmeme borcuna riayet ederek, işyerinde mevcut veya bundan sonra yürürlüğe konulacak işyeri prosedür hükümleri gereğince yerine getirmek ile yükümlüdür.
C107: 4. DİSİPLİN CEZALARININ TANIMLARI VE SONUÇLARI
C108: 4.1. Yazılı İhtar: Çalışanın, 4857 sayılı İş Kanunu’nun 25.maddesi uyarınca haklı nedenle derhal feshe neden olacak ağırlıkta bulunmamakla birlikte, iş sözleşmesine ve kanuna aykırı davranışları, fiziki ve mesleki yetersizliği, işyerinin normal işleyişini ve yürüyüşünü bozan, iş görme borcunun gerektiği şekilde yerine getirilmesini engelleyen, iş yerindeki uyumu olumsuz yönde etkileyen hallerde yazılı olarak uyarılması ve savunmasının alınmasıdır.
J114: Sayfa 1 / 6
D116: DİSİPLİN YÖNETMELİĞİ PROSEDÜRÜ
D118: =D63 -> 0
C123: Çalışan, dikkat çekme ve uyarı niteliğindeki yazılı ihtar sonrasında tanıklar huzurunda yazılı olarak savunma vermediği ve/veya imtina ettiği takdirde uyarı sebebinin haklılığını kabul ve ikrar etmiş sayılır. Bu cezanın verilmesinde kurul kararına gerek olmaksızın, çalışanın bağlı olduğu birim yöneticisi tek başına yetkilidir. Çalışana tebliğ edilen yazının bir örneği sicil dosyasına konulmak üzere İnsan Kaynakları’na gönderilir. 4.1.1. Yazılı İhtar Gerektiren Durumlar Yöneticisinin bilgisi olmaksızın işe geç gelmek, işten erken ayrılmak, Genel görgü kurallarına ve işyerinin çalışma prensiplerine aykırı davranış sergilemek, İşyerinin genel tasarruf ilkelerine dikkat etmemek, Görev ve sorumluluklarını yerine getirmemek, ilgisizlik ve düzensizlik göstermek veya prosedürlere uymayacak şekilde yerine getirmek, Ekip çalışmasını aksatacak tavır ve davranışlarda bulunmak, Görevi başından izinsiz ayrılmak veya görev saatlerinde başka işlerle uğraşmak (Bilgisayar oyunları vb.), İşyerine ait telefonu geçerli bir neden olmadan, işini aksatacak veya hattı istismar edecek şekilde özel görüşmeleri için kullanmak, E-posta hesabını iş dışındaki mailler için kullanmak, İşyerinde açıkça duyurulmuş ve uygulanmakta olan prosedür ve yönetmeliklere uymamak, İşçi sağlığı ve iş güvenliği ile ilgili kurallara uymamak, işyerinin zorunlu kıldığı test, aşı vb. uygulamaları yerine getirmemek veya takibinde gereken hassasiyeti göstermemek, Yöneticilerine, müşterilere veya iş arkadaşlarına kaba, saygısız, nezaketsiz davranışlarda bulunmak, Geçerli bir neden olmaksızın müşterilerle yeterince ilgilenmemek veya bekletmek, Gerektiğinde yöneticileri tarafından kendisinden istenen rapor, bilgi, belge vb. zamanında vermemek veya yanlış bilgi vermek, Kendi sorumluluğunda olan makine, malzeme ve tesisata gerekli özeni göstermemek, Mesai saatleri içerisinde gizli veya açık olarak işyeri ve ek alanlarda sigara kullanmak. Yukarıda anılmayan ve İş Kanunu’na göre derhal feshe neden olacak ağırlıkta bulunmayan her türlü hallerde yazılı ihtar verilebilir. 4.1.2. Yazılı İhtarın Sonuçları Yazılı ihtar cezası kişinin performans değerlendirmesinde, terfi veya görev değişikliklerinde ve iş sözleşmesinin feshi hallerinde dikkate alınır. 4.1.3. Kınama Çalışanın, iş görme borcunu 4857 sayılı İş Kanunu’nda hüküm altına alınan çalışanın işi kendisinin yapması, işin özenle yapılması, itaat borcu, özel haller, kuruma sadakat borcu, rekabet etmeme borcuna riayet ederek, çalışmalarındaki tavır ve davranışlarında geliştirmesi gereken yanlarıyla ilgili yazılı olarak kınanmasıdır. Kınama, kınama ve ağır kınama olmak üzere iki biçimde uygulanır. 4.1.4. Kınama Cezasını Gerektiren Haller Yöneticisinin izni olmaksızın devamsızlık yapmak, işe geç gelmeyi veya işten erken ayrılmayı alışkanlık haline getirmek, Yöneticilerine, müşterilere veya çalışma arkadaşlarına karşı onur kırıcı davranışlarda bulunmak ve/veya kişiliklerine yönelik hakaret etmek, İşyeri ahengini bozacak şekilde arkadaşları ile geçimsizlik çıkarmak, Çalışma arkadaşlarına karşı yersiz suçlamalarda bulunmak ve bunları ispatlayamamak,
J171: Sayfa 2 / 6
D173: DİSİPLİN YÖNETMELİĞİ PROSEDÜRÜ
D175: =D118 -> 0
C180: Yönetimi altındaki çalışanın yönetim ve denetimine gereken dikkati göstermeyerek yolsuzluk yapılmasına elverişli bir ortamın doğmasına yol açmak, İşyerince görevlendirilen haller hariç olmak üzere, işyeri yönetiminden yazılı izin almaksızın ve/veya işyeri ve çalışan arasında yapılmış özel sözleşmelerde belirtilen koşullar saklı kalmak üzere, izin süreleri içinde veya dışında ücretli veya ücretsiz başka bir işte çalışmak veya görev yapmak, her türlü şirket, ticaret veya sanayi kuruluşlarında yönetim kurulu üyeliği veya denetçiliği yapmak, Birlikte çalıştığı çalışanın suç sayılabilecek hal ve hareketlerini zamanında yöneticilerine bildirmekten kaçınmak, İşyerine ait defter, fatura vb. kayıt ve iş ile ilgili belgeleri kaybetmek veya kaybolmasına sebebiyet vermek, Kullanılması veya muhafazası kendisine bırakılmış olan makine ve tesisata gerekli özeni göstermeyerek hasara uğratmak ve/veya kaybetmek, İşyeri tarafından kullanımına verilmiş her türlü şifreyi başkasına açıklamak, kullanımına izin vermek veya başkasına ait şifreyi Kefalet haricinde borçlanmak suretiyle kanuni takibe maruz kalmak. 4.1.5 Kınama Cezasının Sonuçları Kınama cezası bir yıl süre ile terfi etmeyi engeller. Çalışan yıl içinde ödenen her türlü primden ve/veya ödenekten yoksun kalır ve kınama cezası, kişinin performans değerlendirmesinde dikkate alınır. 4.1.6 Ağır Kınama Cezasını Gerektiren Haller İlgisizlik ve dikkatsizlik nedeniyle yanlış ve/veya eksik işlem yaparak veya görevin gerektirdiği işlemleri geciktirerek işyerini zarara sokmak ve/veya güç duruma düşürmek, Görevli olmadığı halde makine, donanım, fiziksel veya bilgisayar ortamındaki bilgileri karıştırmak ve bu durumun gizliliğini ihlal etmek suretiyle bu bilgileri başkalarıyla paylaşmak, Prosedüre uygun olarak verilen talimatları yerine getirmemek veya eksik yapmak suretiyle işyerini zarara sokmak, Şahsen karşılanması gereken giderleri işyerine ödetmek, Kasıtlı olarak üstlerine yanlış bilgi vermek, bildirilmesi gereken hususları saklamak veya disiplin kurulu ya da soruşturmalarda gerçeğe aykırı bildirimde bulunmak, haklı bir neden bulunmaksızın ifade vermekten kaçınmak veya soruşturmayı güçleştirmek, İşyeri dahilinde yapılan bir yolsuzluğu bilerek haber vermemek, Görevin yerine getirilmesinde politik düşünce, kişisel yakınlık, antipati, kin veya benzeri sebeplerle hastalar ya da çalışanlar arasında ayırım yapmak, Müşterilere ait bilgilerin gizliliği ilkesine uymamak Görevli olmadığı halde basın ve/veya medyaya kurumla ilgili açıklamalarda bulunmak, İşyerine ilişkin her türlü gizlilik niteliği taşıyan bilgi ve belgeleri 3.şahıs ve/veya kurumlarla paylaşmak, İşçi sağlığı ve iş güvenliği ile ilgili kurallara uymamak, işyerinin zorunlu kıldığı test, aşı vb. uygulamaları yerine getirmemek ve/veya takibinde gereken hassasiyeti göstermemek suretiyle kendisinin, çalışma arkadaşlarının veya hasta/hasta yakınlarının sağlığını riske atmak, Astlarından borç almak veya onları kefil göstermek suretiyle borçlanmak. Ağır Kınama Cezasının Sonuçları Ağır kınama cezası 2 yıl süre ile terfi etmeyi engeller, çalışan yıl içinde ödenen her türlü primden yoksun kalır ve kişinin performans değerlendirmesinde dikkate alınır.
J228: Sayfa 3 / 6
D230: DİSİPLİN YÖNETMELİĞİ PROSEDÜRÜ
D232: =D175 -> 0
C237: 4.2 Görevden Çıkartma 4857 İş Kanunundan doğan fesih hakkı saklı kalmak üzere çalışanın, bir daha işyerinde çalıştırılmamak üzere iş akdinin fesh edilmesidir. 4.2.1 Görevden Çıkartma Cezasını Gerektiren Haller Kumar anlamına gelecek şekil ve ölçüde oyun oynamayı alışkanlık haline getirmek veya kumar oynamak, Alkol veya yasalarca kullanılması suç sayılan uyuşturucuların müptelası olmak, görev esnasında bunlardan birini kullanmak veya içkili bir şekilde işyerine gelmek, Hırsızlık, dolandırıcılık, sahtecilik yapmak ve diğer yüz kızartıcı suçlardan birini işlemek veya üç aydan fazla hapis cezasını gerektiren suçlardan hüküm giymek, İşçi sağlığı ve iş güvenliği ile ilgili kurallara uymamak, işyerinin zorunlu kıldığı test, aşı vb. uygulamaları yerine getirmemek veya takibinde gereken hassasiyeti göstermemek suretiyle kendisinin, çalışma arkadaşlarının veya müşterilerin herhangi bir şekilde zarar görmelerine veya hayati tehlikeye neden olmak, Özel çıkar karşılığı görevini veya yetkilerini kötüye kullanmak veya kullandırmak, işyerine ait para, mal veya malzemeyi zimmetine geçirmek, İş akdi yapıldığı sırada gerçeğe aykırı bilgi ve belgelerle işyerini yanıltmak, İş sözleşmesinde yer alan, uyulması zorunlu ve çalışan tarafından da kabul edilmiş yükümlülükleri yerine getirmemek, Müşterilerden veya işbirlikçi firmalardan çıkar sağlayarak doğrudan doğruya veya aracı eliyle hediye veya rüşvet almak, Müşterilere ait bilgileri resmi mercilerin yasal taleplerine verilecek cevap dışında hastanın açıklanmasını istemediği üçüncü kişilere açıklamak yoluyla gizlilik ilkesini ihlal etmek, İşyeri tarafından kendisine verilmiş her türlü şifreyi başkasına açıklamak, kullanımına izin vermek veya başkasına ait şifreyi izinli veya izinsiz kullanmak suretiyle işyerinin zararına neden olmak, Her türlü belge, bilgi ve dokümanı tahrip etmek, ettirmek veya kötü niyetle yok etmek veya ettirmek, sahte belge düzenlemek, Görevli olmadığı halde makine, donanım, fiziksel veya bilgisayar ortamındaki bilgileri karıştırmak ve bunları başkalarıyla paylaşmak suretiyle kuruma zarar vermek, İşyeri içinde veya görev sırasında arkadaşları, müşterileri ile kavga etmek, olay çıkartmak veya işyeri dışında olay çıkartarak işyerinin şeref ve haysiyetine gölge düşürmek, Yöneticilerine veya iş arkadaşlarına şeref ve namuslarına dokunacak yalan beyanlarla veya bunları lekelemek kastı ile şeref haysiyet kırıcı, ispatlayamayacağı ihbar ve şikayetlerde bulunmak, Yöneticilerine, iş arkadaşlarına veya müşterilerine tehdit veya tacizde bulunmak. 4.2.2 Görevden Çıkartma Cezasının Sonuçları Görevden çıkarma cezası alan çalışanın iş akdi bildirimsiz ve tazminatsız olarak fesih edilir. 4.3 Disiplin Cezalarına İlişkin Genel Hükümler Çalışan tarafından, disiplin yönetmeliğinde yer alan kurallarda tanımlı olmayan, ancak firma bünyesindeki uyumlu ve verimli çalışma ortamını zedeleyecek, bozacak tavır ve/veya davranışın sergilenmesi durumunda, disiplin yönetmeliğinde yer alan ve ona en yakın ve/veya benzer madde üzerinden işlem yapılır.
J285: Sayfa 4 / 6
D287: DİSİPLİN YÖNETMELİĞİ PROSEDÜRÜ
D289: =D232 -> 0
C294: 4.3.1. Benzeri Hal ve Eylemler Çalışan tarafından, disiplin yönetmeliğinde yer alan kurallarda tanımlı olmayan, ancak firma bünyesindeki uyumlu ve verimli çalışma ortamını zedeleyecek, bozacak tavır ve/veya davranışın sergilenmesi durumunda, disiplin yönetmeliğinde yer alan ve ona en yakın ve/veya benzer madde üzerinden işlem yapılır. 4.3.2. Tekrar Kişilerin, yönetmelik kapsamındaki kurallara aykırı düşen tavır, davranış ve olayları tekrarlaması durumunda bir üst ceza uygulanır. 4.3.3. İş Yasası Hükümlerinin Saklılığı Bu yönetmeliğin uygulanmasında 4857 sayılı İş Kanunu’nun ilgili madde hükümlerinin uygulanma hakkı saklı tutulur. 4.4. Disiplin Kurulu 4.4.1. Amaç ve Görevi Kurul, işyeri hizmetlerinin genel hedef ve politikalarına uygun olarak yürütülmesini, işyeri karlılığı ve saygınlığı ile güven, gizlilik ve etik kurallara bağlı çalışma ilkelerinin korunmasını sağlamak ve desteklemek amacı ile kurulmuştur. Kurul, görevlerini yaparken hatalı eylemlerde bulunanlar hakkında ilgili değerlendirmelerin karara bağlanması ile görevlendirilmiştir. 4.4.2. Disiplin Kurulunun Yetkisi Kurul, işyeri hizmet ve işlemlerini düzenleyen her türlü yazılı kaynağın belirttiği ve/veya zorunlu kıldığı işlem ve sorumlulukların, etik kurallara ve yasal mevzuata uygun olarak yerine getirilmesini teminen çalışanlar hakkında caydırıcı, engelleyici ve düzeltici önlem alarak bu prosedürün öngördüğü cezaları vermeye yetkilidir. 4.4.3. Disiplin Kurulu Üyeleri İnsan Kaynakları biriminin önerisi ve Genel Müdür’ün onayı ile seçilen iki işveren temsilcisi ve kurumdaki en kıdemli çalışanlar arasından seçilen, iki işçi temsilcisi olmak üzere dört üyeden oluşur. Üyelerden birisi başkan tayin edilir. Ayrıca, kurulun asil üyesi kadar yedek üyesi vardır. İnsan Kaynakları Müdürü kurulun doğal üyesidir ve oy hakkı yoktur. 4.4.4. Kurula Sevk ve Gerekli Belgeler 4.4.4.1.Olayla ilgili “Tutanak Formu” bölüm yöneticisi tarafından tutulduktan sonra kişinin savunması alınır. 4.4.4.2. “Savunma İstem Formu” ilgili tutanakla birlikte bağlı olduğu müdürlüğe gönderilir ve buradan da ilgili direktörün onayı alınarak kurula sevk istemiyle İnsan Kaynakları birimine iletilir. 4.4.4.3. Tüm bu işlemler, olay meydana geldikten sonra en geç 2 -3 gün içinde tamamlanır. 4.4.4.4. Kurula sevk edilen çalışan hakkında; kendisine isnat olunan suçla ilgili belgeler ve tutanaklar İnsan Kaynakları birimi tarafından aynı gün içinde kurula gönderilir. 4.5. Kurulun Toplanması Disiplin Kurulu, gerekli belgelerin kurul başkanına sevkinin en geç ertesi günü, başkanın talebi ile toplanır. Toplantı yeter sayısı, salt çoğunluk olup, toplantının asil üyelerle yapılamaması halinde, çoğunluk yedek üyelerle temin edilir.
J342: Sayfa 5 / 6
D344: DİSİPLİN YÖNETMELİĞİ PROSEDÜRÜ
D346: =D289 -> 0
C351: 4.5.1. Karar Alınması 4.5.1.1.Kurulda, başkan da dahil her üyenin bir oyu vardır. Kararların alınmasında oy çokluğu ilkesi uygulanır. Oyların eşitliği halinde, başkanın oyuna itibar edilir. 4.5.1.2. Kurul, ceza verilmesi istemiyle sevk edilen personeli dinler ve/veya yazılı savunmasını alır. Kurul kararını, konu ile ilgili yapılacak ilk toplantı tarihinden itibaren 3 gün içinde verir. 4.5.1.3. Verilecek cezaların tespiti sırasında; Suç sayılan eylemin işyeri bünyesinde meydana getirdiği zararın maddi ve manevi önem derecesi, Suç işleyen çalışanın, görev ve unvanının önemi, işyerindeki tutumu, davranışları ve kişiliği hakkındaki genel kanaat, Suç sayılan eylemin sebepleri, göz önünde bulundurulur. 4.6. Kararların Onaylanması Kurul kararları genel müdür tarafından onaylandıktan sonra geçerlilik kazanır ve dosya ile birlikte aynı gün içinde gerekli işlem yapılmak üzere İnsan Kaynakları birimine gönderilir. 4.7. Disiplin Cezalarının Sicile Geçirilmesi Karar, ilgili çalışanın bağlı olduğu direktörlüğe yazılı olarak bildirilir ve oradan da ilgili müdürlüğe gönderilerek bu yönetici tarafından çalışana tebliğ edilir. Disiplin cezası kişinin sicil dosyasına işlenir. 5. İLGİLİ DOKÜMANLAR 5.1 Tutanak Formu 5.2 Savunma İstem Formu
C388: İş Güvenliği Uzmanı | G388: İşveren / İ.Vekili
C389: =KAYIT!C8 -> 0 | G389: =KAYIT!C7 -> 0
...

Sheet İÇ EMNİYET YÖNETMELİĞİ
C10: İÇ EMNİYET YÖNETMELİĞİ
F44: =KAYIT!C6 -> 0
C47: =KAYIT!C1 -> 0
E59: İÇ EMNİYET YÖNETMELİĞİ
E61: =KAYIT!C1 -> 0
C64: GENEL ESASLAR 1. KAPSAM Bu iç yönergenin dosyada adı ve adresi belirtilen alanda faaliyet gösteren işyerinde çalışan tüm personeli, Şirkete iş yapan Alt işverenin geçici ve daimi personelini ve Firmaya ait tesis, havuz, mal ve malzemeleri kapsamaktadır. 1.1. İŞ SAĞLIĞI VE İŞÇİ GÜVENLİGİ POLİTİKASI (İSİG) Yaptığımız işin tüm aşamalarında ve her kademesindeki çalışanlarımızın, taşeron firmaların,tedarikçilerimizin ve dışarıdan gelen ziyaretçilerimizin sağlıklı ve iş güvenliğinin en üst seviyede sağlanarak güven içerisinde bulunmaları,son teknolojiyi takip ederek sürdürülebilir kalkınma ilkeleri doğrultusunda, çalışanının hayatının korunması ilkesi tüm faaliyetlerimizin vazgeçilmez bir parçasıdır.Çalışan sağlığını, tüm imkânlarımızla ve yasaların tarif ettiği en üst seviyede korumak başta gelen amacımızdır. Bütün bunlara dayanarak; -Faaliyetlerimizin tamamında,yasaların belirlediği şartları çalışanlarımıza,tedarikçilerimize ve ziyaretçilerimize sağlamayı ve uygulamayı, -İş Sağlığı ve Güvenliği performansımızı artıracak tüm yatırımlara zaman, insan ve maddi kaynak ayırmayı, -Çalışanlarımızın,tedarikçilerimizin ve çevremizdekilerin İSİG bilincini artırmak için gereken tüm çalışmaları gerçekleştirmeyi, -Yaptığımız işte her zaman son teknolojiyi kullanarak en az kazaya maruz kalan kuruluş olmayı -Yaptığımızişte, doğal yaşama zarar vermeden, insanasaygılı, yasalara uygun çalışma bilincini, -Yönetim olarak sürekli iyileştirme çerçevesinde, sektöründeki tüm yasal gereklere uyarak ve teknolojik gelişmeleri bünyesine katarak fiziki emniyet ve iş güvenliği sağlayarak sağlıklı,mutlu ve verimli insan, görüşü ile risk seviyelerini en aza indirmeyi hedeflemekte, -Kuruluşun tüm çalışanları kullanarak güncel, uygulanabilir, sürekligelişen, her kademedeki çalışanın görüşüne açık, yasal gerekleri ve geçerli uygun bir iş sağlığı ve iş güvenliği yönetim sistemini gerçekleştirmeyi, TAAHHÜT EDERİZ. 2. GENEL KURALLAR 2.1. İşyeri ilan tahtasına veya panosuna işyerinin muhtelif kısımlarına asılmış bulunan veya asılacak olan iş sağlığı ve güvenliği kuralları okunacak ve bu kurallara uyulacaktır. 2.2. İş yerinde İş sağlığı ve güvenliği konusunda alınmış bulunan tüm tedbirlere tam olarak uyulacaktır. 2.3. İşyeri, Yönetici ve Amirleri tarafından, zaman zaman tarafınıza bildirilecek yazılı ve sözlü kurallara uyulacaktır. 2.4. Şahsınıza verilen görev, size tarif edildiği şekilde yapılacak, kendi işinizden başka bir işe karışılmayacak, amirinizin verdiği emir ve talimatlara kesinlikle uyulacaktır. 2.5. İşyerinin muhtelif yerlerine, çeşitli maksatlar için asılmış bulunan uyarı(ikaz) levhalarını tek tek okunacak ve bu levhalardaki uyarılara eksiksiz uyulacaktır. 2.6. İşin gereği olarak şahsınıza verilen kişisel koruyucular, örneğin; baret(miğfer), emniyet (güvenlik) kemeri, lastik çizme, gözlük vs. çalışma esnasında devamlı olarak kullanılacaktır. Bu malzemeler eskir, kırılır veya kaybolursa amirinize haber vererek ve izin alarak ambardan yenisi alınacaktır. İşinizin gereği ve can güvenliğiniz için çok önemli olan bu koruyucular olmadan çalışma yapılmayacaktır. 2.7. Düşme, kayma tehlikesi olan ve üç metreden daha yüksek kısımlarda çalışırken mutlaka güvenlik (emniyet) kemeri kullanılacaktır. Bu gibi yerlerde emniyet kemersiz çalışmak kesinlikle yasaktır.
K113: Sayfa 1 / 12
E116: İÇ EMNİYET YÖNETMELİĞİ
E118: =KAYIT!C1 -> 0
C121: 2.8. Şahsınıza verilen kişisel koruyucu malzemeler iyi ve temiz bir şekilde kullanılacak ve muhafaza edilecektir. 2.9. Beraber çalıştığınız iş arkadaşlarınızı ve işyerinde çalışan diğer çalışanları kazaya uğratmayacak şekilde dikkatlice çalışılacak, bu konuda işe yeni giren personele yardımcı ve yol gösterici olunacaktır. 2.10. İşyerinde çalıştığınız sürece, sivri uçları veya keskin kenarları bulunan malzeme ve artıklar gelişigüzel yerlere atılmayacak ve ortalıkta bulundurulmayacaktır. Bu tür malzemeler, onlar için ayrılmış bölümlerde toplanacaktır. 2.11. İşyerinizde çalıştığınız sürece, kazaya sebep olacak veya çalışanları tehlikeli durumlara düşürecek şekilde malzeme istif edilmeyecek ve araçlar bulunmaları gereken yerden başka yerlere bırakılmayacaktır. 2.12. Çalışanların, yılda bir kez, periyodik sağlık kontrolleri yapılarak, Ağır ve Tehlikeli İşlerde çalışabilir raporları yenilenecektir. 2.13. Kuvvetli rüzgâr alan kısımlarda, yetkili ve sorumluların izni ve haberi olmadan çalışılmayacaktır. 2.14. Yemekhane ve çay ocağı personelinin, üç ayda bir kez, portör muayeneleri yapılacaktır. 2.15. Meydana gelen en ufak iş kazası, işyeri ilgili ve sorumlularına haber verilecektir. 2.16. Sigara içilmesi yasaklanan yerlerde, kesinlikle sigara içilmeyecek, ateşle yaklaşılmayacak, açık alevli cihaz kullanmayacak, kaynak yapılmayacaktır. 2.17. İşyerinde meydana gelecek en küçük bir yangın derhal sorumlu ve ilgilerine haber verilecektir. 2.18. İş makinelerinin üzerinde operatörden başkası bulunmayacaktır. 2.19. İskeleler sağlam malzemelerden yapılacaktır. 2.20. İskeleler, çalışmaya başlamadan önce kontrol edilecek, herhangi bir arıza mevcutsa, durumu sorumlu ve ilgilere haber verilecek ve sorun giderilmeden çalışılmayacaktır. 2.21. İskelede, herhangi bir nedenle kayganlık meydana gelmişse, bu sorun giderildikten, sonra çalışılacaktır. 2.22. İskelelerde korkuluksuz çalışılmayacaktır. 2.23. İskele sökümü yukarıdan aşağıya doğru yapılacaktır. 2.24. İskele sökümü sırasında alt tarafta hiçbir kimse bulundurulmayacaktır. 2.25. Her türlü arıza ve sorun derhal sorumlu ve ilgililere haber verilecektir. 2.26. Arızalı alet, cihaz, makine ve tezgâh kullanmayacaktır. 2.27. Elektrikle ilgili arızalar elektrikçiye, elektrik servisine veya işyeri elektrik sorumlusuna haber verilecektir. 2.28. Elektrik panosu veya tablosunun üzerine, çevresine hiç bir şey koyulmayacaktır. 2.29. Elektrik pano veya tablosu çevresine su dökmek, su sıkmak kesinlikle olarak yasaktır. 2.30. İşyerinin muhtelif kısımlarında bulunan enerji nakil hattına, herhangi bir nedenle yaklaşılmayacak ve dokunulmayacaktır. Ayrıca bu hatlara demir, boru veya buna benzer malzemeler yaklaştırmayacak ve dokundurulmayacaktır. Ölüm tehlikesi vardır. 2.31. Bakım ve Onarım işlerinde; atölye disiplinine riayet etmek şarttır.Alet ve edevat zimmetle alınıp verilecek. Kullandığı alet ve edevatı başkalarına kullanmak üzere vermek veya başkalarından kendine ait olmayan aleti ve edevatı almak yasaktır. 2.32. Arızalı takım ve malzeme kullanmak yasaktır. 2.33. Yüksek yerlere izinsiz çıkmak, gezmek tehlikeli ve yasaktır. 2.34. Kırık ve eskimiş merdiven kullanılmayacaktır.
K170: Sayfa 2 / 12
E173: İÇ EMNİYET YÖNETMELİĞİ
E175: =KAYIT!C1 -> 0
C178: 2.35. Yangın söndürme tüpleri, altı ayda bir periyodik olarak, yetkili servislerce kontrol edilecektir. 2.36. Ağır yük kaldırırken bacaklar bükülecek, yük belinizle değil, bacaklarınızla kaldırılacaktır. 2.37. Yanıcı malzeme, kaynak işlerinden uzak tutulacaktır. 2.38. Boşalan yangın söndürme cihazları doldurulacaktır. 2.39. Gürültülü işlerde çalışanların, yılda bir kez kulak odyogramları çektirilecektir. 2.40. Yılda bir kez elektrik tesisat kontrolü yapılacaktır. 2.41. Yılda bir kez topraklama ölçümleri yapılacaktır. 2.42. Yılda bir kez paratoner kontrolü yapılacaktır. 2.43. Yılda bir kez akaryakıt deposu statik elektrik kontrolü yapılacaktır. 2.44. Yılda bir kez içme ve kullanma suyu analizleri yapılacaktır. 2.45. Kompresörlerin, yetkili kişiler tarafından, yılda bir kez, periyodik kontrol ve testleri yapılacaktır. 2.46. Alkollü olarak işyerine gelmek veya çalışmak kesinlikle yasaktır. 2.47. Kazanların ve basınçlı kapların, yetkili kişiler tarafından, yılda bir kez periyodik kontrolleri ve testleri yapılacaktır. 2.48. İşyerlerinde çalışan alt işverenlerde, iş sağlığı ve güvenliği talimatlarına uymakla yükümlüdürler. 2.49. Ölüm tehlikesi işareti olan yerlere ve ilgili personelden başkasının girmesi yasak olan yerlere müsaadesiz girmek yasaktır. 2.50. Kendi iş mahalli dışındaki işyerlerinde dolaşmak yasaktır. 2.51. Görevli olmadığı halde şalter ve kontrol tablolarına müdahale etmek açmak veya kapamak yasaktır. 2.52. Vinçlere kaldırma gücünden fazla yük vurmak ve çalışırken altlarında durmak tehlikeli ve yasaktır. 2.53. Amirinin haberi olmaksızın, normal çalışma yerleri dışındaki tehlikeli yerlere tamir veya başka amaç ile girmek yasaktır. 2.54. Çalışan iş makinelerinin(Ekskavatör, loder,vb.) etki alanlarına girmek yasaktır. 2.55. Bir yangın vukuunda; a. Telaşlanmayınız. b. Bulunduğunuz yerde yangın ihbar düğmesine basınız veya varsa çançalınız. c. İtfaiye teşkilatına haber vermek için telefon ediniz. d. Yangın yerinin adresini en kısa ve doğru şekilde bildiriniz. e. Mümkün ise yangının cinsini de bildiriniz.(Bina, benzin, motorlu vasıtavs. gibi) f. Yangını çevrenizdekilere ve ilgililere en kısa sürede duyurunuz. g. İtfaiye gelinceye kadar yangını söndürmek için elde mevcut, araç gereç ve imkânlardan faydalanmaya çalışınız, bu işlemleri yaparken kendinizi ve başkalarını tehlikeye atmayınız. h. Yangının yayılmasını önlemek için yanıcı maddeleri yangın mahallinden uzaklaştırınız. i. Görevlilerden başkasının yangın sahasına girmesine mani olunuz. 2.56. Her türlü bakım ve tamir için ilgili amire haber vermeden işe başlanmayacaktır. 2.57. Bakım yapılacak makinelerin kumanda düğmeleri, şalterlerine ve yol vericilerine, “Dikkat bakım var. Yol verme” ikaz ve uyarı levhaları asılacaktır. 2.58. Her türlü kaldırma araçlarının, yetkili makamlara ya da kişilere, üç ayda bir periyodik kontrolleri ve testleri yaptırılacaktır. 2.59. Caraskallar ve Forkliftler hareket halindeyken yanında ve altında durmak yasaktır. 2.60. İşyerinde makine ve aletleri görevlisinden başkasının kullanması yasaktır.
K227: Sayfa 3 / 12
E230: İÇ EMNİYET YÖNETMELİĞİ
E232: =KAYIT!C1 -> 0
C235: 2.61. Makine çalışırken tamirat ve temizlik yapmak yasaktır. 2.62. Presin altına ve üstüne girmek çıkmak (Dururken ve Çalışırken) yasaktır. 2.63. Asit üzerine su dökmeyiniz, tehlikeli ve yasaktır. 2.64. Herhangi bir makinenin normalin üstünde gürültü yapması halinde, makine derhal durdurulacak ve derhal yetkiliye bildirilecektir. 2.65. Yeklinin iznini almadan makinelere ait muhafazalar(koruyucular) çıkartılmayacaktır. 2.66. Elektrikle çalışan aletlerin elektrik kablolarında olacak tahribatları kontrol etmeden çalıştırmak ve görülen anormallikleri elektrikçilere haber vermemek tehlikeli ve yasaktır. 2.67. Göreviniz olmadıkça hiç bir elektrik teline dokunmayınız, tehlikeli ve yasaktır. 2.68. Sigorta ve şalterleri devreden çıkarmadan bakıma başlama, kimseye itimat etme, kendi kontrolünü kendin yap. 2.69. Yüksek ve alçak gerilimin bulunduğu yerlere yaklaşmak tehlikeli ve yasaktır. 2.70. Oksijen ve gaz tüplerini sıcak yerlerde bırakmak veya bu tür yerlerde kullanmak tehlikeli ve yasaktır. 2.71. Oksijen tüplerini sıcaktan ve ateşten koruyunuz, çarpmayın ve düşürmeyin. 2.72. Elektrik kaynak makinesinin gövdesi, kaynak masası veya kaynak yapılan parça topraklanmadan kaynak yapmak yasaktır. 2.73. Kaynak işi bittiği zaman makinenin elektriği kesilecektir. 2.74. Maskesiz kaynak yapmak kesinlikle yasaktır. 2.75. Kaynak yapan kişi etrafındakilerin güvenliğinden sorumludur. 2.76. Yetkilinin izni veya emri olmadan atölye haricinde kaynak veya tamirat yapmak yasaktır. 3.GENEL GÜVENLİK ve ZİYARETÇİLER 3.1.GÜVENLİK GÖREVLİLERİ ÖZEL TALİMATI a. Güvenlik görevlileri kendilerine ait her türlü tesisat ve malzemenin korumasını sağlar. b. Kapı giriş trafiği; Acil durumlar için her zaman araç tahliyesine uygun ve temiz bulunacaktır. c. İşletmeye gelen tüm personeli nezaket kuralları içerisinde karşılayıp ziyaretçilerin tanıtım kartlarını alıp ziyaret edeceği personellere irtibat kurarak ziyaretçi kayıt işlerinin yapılmasını, işletmemizin emniyet, kaide ve kurallarını kısa ve öz olarak hatırlatarak ziyaretçinin emniyetli bir şekilde tesise girmesi ve gitmesi temin edilecektir. d. Tüm araç sürücülerinin trafik kurallarına uymaları için ikaz edilecektir. Bunlar azami hız sınırına, araçların park yeri ve yönleriyle ilgili kurallara uymaları gerekmektedir.Dosyada adı ve adresi bulunan işletmeyeaittüm araçların kullanımında “Araç Kullanma Talimatı” çerçevesinde yürütülmesini sağlamak. e. Acil çıkışlar için kapıların önlerinin kapatılmaması, her an trafiğe açık olmasının sağlanması gerekmektedir. f. Acil durumlarda ne yapacaklarını çok iyi bilecek haberleşmede öncelik sırasına göre ilgililere bildirimin yapılmasını sağlayacaklardır. Mesai haricinde acil durum planını uygulamaya koyacaklardır. g. Durumlarından şüphe ettikleri şahıs veya şahısları en yakın amirlerine bildirerek, tesis içine sızmalarını önleyecek gerektiğinde emniyet birimlerine gerekli ihbarı yapacaktır.h. Fabrika içerisinde ziyaretçi personelin yalnız başına üst düzey yöneticilerin izni olmadan dolaşmasına müsaade edilmeyecektir. i. Fabrika içerisindeki Kaldırma Araçlarının “İndirme Kaldırma Faaliyetleri Kontrol Prosedürü” çerçevesinde sertifikasız kişilerin kullanımlarının engellenmesini sağlayacaktır. j. Mesai saatleri haricinde üst düzey yöneticilerin izni olmadan tesise hiçbir şahsı alamazlar. k. Acil konumlar için haberleşme cihazlarının kontrolünü sürekli yapacaklardır. l. Üst düzey yöneticilerin izni olmadan kapıdan ve görev yerlerinden ayrılmayacaklardır.
K284: Sayfa 4 / 12
E287: İÇ EMNİYET YÖNETMELİĞİ
E289: =KAYIT!C1 -> 0
C292: 3.2. ZİYARETÇİLERLE İLGİLİ TANIMLAR a. Tatil günlerinde fabrikada çalışacak işçilerin isimleri, çalışacağı gün, işyeri amirince bir gün önceden tespit edilir. İsimleri listede olmayanlar Fabrikaya sokulmazlar. b. Tatil günlerinde fabrikaya ziyaret maksadıyla gelen yabancılar fabrikaya kesinlikle sokulmazlar. 3.3. RESMİ ZİYARET VE TEFTİŞLER Fabrikaya inceleme, araştırma soruşturma veya denetim amacıyla gelen Bakanlık müfettişlerine ziyaret amaçları sorulur. Durum İlgili amire bildirilir. Alınan Talimata göre hareket edilir. 4. YANGIN EMNİYETİ 4.1. YANGIN İş yerinde yapılan inceleme sonucunda üç çeşit yangın riskinin bulunduğu anlaşılmıştır. Bunlar; (A) sınıfı yangın ,(B) sınıfı yangın ve (C) sınıfı yangınlardır. (A) SINIFI YANGIN Ahşap kâğıt kumaş odun kömür saman ile doğal örtülerden çıkan yangınlardır. Bu sınıftaki yangınlara su, köpüklü yangın söndürme, CO2 yangın söndürme cihazları ile müdahale etmek gerekir. (B) SINIFI YANGIN Akaryakıt, yağ, boya tiner vb diğer parlayıcı madde yangınlarıdır. Bu tür yangınlara (CO2), köpük ve kuru kimyasal tozlu tip yangın söndürme cihazları ile müdahale edilir. ( C ) SINIFI YANGIN Türlü yanıcı gaz maddelerdir,metan, propan,asetilenLpg, tüpgaz, doğalgaz yangınlarıdır Karbondioksit, köpük,Kuru kimyevi toz kullanılarak söndürülür. (D) SINIFI YANGIN Metal yangınları, sodyum,potasyum,titanyum,mağnezyum, KKT ile söndürülür Elektrik yangınlarıda ayrı bir gurup olarak değerlendirilmekte, öncelikle akım keilir,sonra söndürme işlemi yapılır. 4.2. YANGIN TEKNİK EMNİYET TALİMATI a. Yangını ilk gören kişi yangın alarmını devreye sokarak tüm fabrikaya yangını haber verir. En yakın telefonla İtfaiye’ye, yetkili amirine ve kapıdaki güvenlik görevlisine bildirir. b. Yangın haberini veren kimse her iki yere de kendi ismini ve yangın yerini açıkça heyecana kapılmadan bildirir. c. En yakın yerdeki yangın söndürme cihazı ile yangını söndürme mücadelesine başlanır. d. Kapıdaki güvenlik görevlisi, durumu İşletme Müdürebildirir. Kapıyı kapar yalnız görevlileri içeri alır. e. Fabrika içerisinde teşkil eden ekipte;( söndürme, kurtarma, ilk yardım) isimleri yazılı personel görevlerini ifa ederler. İtfaiye gelince görevlerini itfaiyeye devir ederler ve itfaiyenin emrine girerler. f. Güvenlik görevlileri ve yangın koruma ekibinde görevli personel yangın yerinde bulunan görevlilerden başkalarını yangın yerine sokmazlar.
K341: Sayfa 5 / 12
E344: İÇ EMNİYET YÖNETMELİĞİ
E346: =KAYIT!C1 -> 0
C349: 4.3. YANGINLA MÜCADELEDE DİKKAT EDİLECEK HUSUSLAR a. Yangın söndürme ekibinde olanlar gerekli malzeme ile derhal yangın yerine intikal eder ve söndürme çalışmalarına katılırlar. b. Panik yaratmadan diğer görevliler görev yerlerinde bulunurlar. c. Yanan cisim sıvı değilse, söndürme maddesi doğrudan doğruya yanan cismin üzerine püskürtülürdumana veya aleve püskürtülmez. d. Yanan Parlayıcı bir sıvı ise ateşin sıçramasına mani olmak için yanmakta olan yüzeyin hemen üzerine püskürtülür. e. Ateş döşemeye veya yere sıçramış ise söndürmeye en yakın yerden başlanır. f. Alev bir duvarı kaplamaya başlamışsa söndürmeye dip taraftan başlanır. g. Yangın elektrik kontağından çıkmış ise cereyan kesilmeden su sıkılmaz. h. Yangın söndürmelerde daima rüzgâr arkaya alınır. i. Yangın söndürüldükten sonra daima bir gözcü bırakılır. 4.4. YANGIN KONUSUNDA ALINACAK EMNİYET TEDBİRLERİ a. Binaların İç elektrik tesisatı planı, mümkünse sayacın yanında, camlı dolap içerisinde bulundurulacaktır. b. İç tesisatta değişiklikler yetkili makamın onayından sonra yapılacaktır. c. Binaların iç elektrik tesisatında mümkünse otomatik sigorta kullanılacaktır. d. Elektrik devrelerine kapasitenin üzerinde akım çekecek şekilde cihaz bağlantısı yapılmayacaktır. e. İşyerinde açık buat, uçları açık veya kopuk kablo, izolesi açık kablo bulunmayacaktır. f. Anahtar veya şalter, çıplak kablo bulunmayacak, sigortaların buşonlarına tel bağlanmayacaktır. g. Likit gaz, iş ve hizmet gereği yetkililerce belirlenmiş yerler dışında her ne maksatla olursa olsun kesinlikle kullanılmayacaktır. h. Likit gazın kullanılması zorunlu olan yerlerde gerekli emniyet önlemleri alınacak, ilgililerce sık sık kontrol edilecek ve kullananlar sorumluluk taşıyacaktır. i. LPG tüplerinin ve benzeri basınçlı gaz tüplerinin kaçak kontrolü veya muayeneleri çıplak alev ile yapılmayacak bu gibi kontrollerde sabun veya deterjan köpüğü ile yapılacaktır. j. Likit gaz tüplerinin bağlantılarında mutlaka kelepçe kullanılacaktır. k. Bulundurulmasında zaruret olan yerlerdeki yanıcı parlayıcı ve patlayıcı maddeler ısıdan uzak ve emniyetli kaplar içinde muhafaza edilecektir. l. İşyeri temiz tutulacak kağıt ve benzeri yanıcı maddeler gelişi güzel etrafa atılmayacaktır. m. İş yerinde izin verilen yerler dışında sigara içilmeyecektir. n. Yanan sigara veya sönmemiş sigara izmaritleri, rast gele yerlere, kağıt sepetlerine veya varillerine atılmayacaktır. o. İş yerinde yağlı bez, üstüpü gibi yanıcı parlayıcı madde ihtiva eden atıklar rast gele yere atılmayacak, bunlar madeni çöp kutularında (Atık Yönetimi Prosedürü çerçevesinde hazırlanan konteynerde) toplanacaktır. p. Sürekli çalışılan iş yeri haricinde kaynak ve pürmüz gibi alev ve kıvılcım çıkartan aletler ile herhangi bir çalışma yapılmadan önce mutlaka sıcak iş izni alınacaktır. q. Parlayıcı ve patlayıcı sıvıların ve maddelerin konduğu tank ve depolar ile boru bağlantıları statik elektriğe karşı uygun bir şekilde topraklanacaktır. r. Yangın araç ve gereç ve cihazların her an kullanılmaya hazır olabilmesi ilgililerce sağlanacaktır. s. Yangın cihaz ve malzemeleri kesinlikle yangından başka maksat için kullanılmayacaktır. t. Çalışma saatleri içinde, işyerindeki hiçbir giriş ve çıkış kapısı kilitli veya bağlı olmayacaktır.
K397: Sayfa 6 / 12
E400: İÇ EMNİYET YÖNETMELİĞİ
E402: =KAYIT!C1 -> 0
C405: 5. PARLAYICI PATLAYICI VE ZARARLI MADDELERLE ÇALIŞMA TALİMATI 5.1. İŞ YERİ BİNALARINDA ALINACAK GÜVENLİK ÖNLEMLERİ a. Parlayıcı, patlayıcı, tehlikeli ve zararlı maddelerle çalışılan işyerimizin tabanları, düz, yanmaz sızdırmaz herhangi bir cismin basit çarpmasıyla kıvılcım çıkarmayacak şekilde beton malzemeden yapılmış ve kolay temizlenebilir tarzda inşa edilmiştir. b. Kullanılan maddelerin, kimyasal bir olay sonucunda işyeri tabanını aşındırıp tahrip etmesi veya parlayıcı, tehlikeli ve zararlı gaz ve dumanlar meydana getirmesi önlenecektir. c. Tabanda yangın söndürme cihazlarının vereceği fazla su ve kimyasal maddelerin ve işyerindeki bütün sıvıların giriş eşiklerinden taşmasını önleyecek şekilde toplanmasını ve arıtmaya götürülmesini sağlayacak drenaj sistemi bulunacaktır. d. Tesisimizin her hangi bir tehlike durumunda işçiler tarafından derhal boşaltılabilecek şekilde tertiplenmiştir. e. İnşaat bakım onarım işlerine başlanmadan önce aşağıdaki tedbirler mutlak suretle alınacaktır. f. İş kısmen veya tamamen durdurulacaktır. g. Departmanda bulunan bütün parlayıcı, patlayıcı tehlikeli ve zararlı maddelerle, bunların bileşimlerine giren diğer maddeler tehlikeli bölgenin dışına çıkarılacaktır. h. Onarılacak kısım bütün parlayıcı, patlayıcı, tehlikeli ve zararlı maddelerin artıklarından ve bulaşıklarından usulüne göre uygun olarak tamamen temizlenecektir. i. İnşaat, bakım ve onarım; teknik yetkili ve sorumlu bir elemanın devamlı nezaretince sağlanacaktır. 5.2. ELEKTRİK TESİSATINDA ALINACAK GÜVENLİK TEDBİRLERİ a. Parlayıcı gaz veya buharların havaya karışması ile patlama tehlikesi bulunan yerlerdeki elektrik alet ve teçhizatı tehlike alanının dışına kurulacaktır. b. Mekanik bir etkiye maruz kalması muhtemel olan yerlerde zırhlı kablolar kullanılacaktır. c. Kablo uçları neme karşı bu tip iletkenlere özgü alev geçirmez şekilde ve özel kapaklarla tecrit edilecektir. d. Sık sık bakıma ihtiyaç gösteren elektrik teçhizatını devreden tamamen ayırma olanağı sağlanacaktır. e. Parlayıcı bir ortamda akım kesici tertibat, kumanda ettiği makine veya cihazın hemen bitişiğinde bulunmadığı hallerde, bunların kontrol, bakım veya onarım sırasında beklenmedik bir anda, gerilim altında kalmasını önlemek için gerekli tedbirler önceden alınacaktır. f. İşyerinde kullanmakta olduğumuz tüm makinelerin gövde topraklaması mutlak suretle olacak ve bunlar kesinlikle sökülmeyecektir. g. Seyyar elektrik cihazları hiçbir şekilde tehlikeli ortamlarda kullanılmayacaktır. 5.3. ÇALIŞMA YERİNDE ALINACAK GÜVENLİK TEDBİRLERİ a. Geniş bir alana yayılmış tesisimiz duvar ile çevrilmiş geceleri uygun bir şekilde aydınlatılması sağlanmış durumdadır. Güvenlik görevlileri gece ve gündüz bu alanları gözetleyeceklerdir. b. Parlayıcı, patlayıcı ve tehlikeli işler genellikle meskûn yerler dışında veya tecrit edilmiş bina ve mahallerde, mümkün olduğu kadar az işçi ile kapalı bir sistem içinde, tekniğin icaplarına göre gerekli tedbirler alınarak yapılmaktadır. c. Tesisimizin güvenlik alanı içerisinde, kızgın veya akkor halinde cisimler ile parlayabilecek veya yangın doğurabilecek her türlü maddenin taşınması ve kullanılması yasaktır. d. Yıldırım tesisatı faal olarak çalıştırılacaktır. Ayrıca denetimi aralıklarla kontrol edilecektir. Yıldırım sisteminin tertibatı kesinlikle kurcalanmayacak ve yetkilisi dâhilinde müdahale
K454: Sayfa 7 / 12
E457: İÇ EMNİYET YÖNETMELİĞİ
E459: =KAYIT!C1 -> 0
